2021-06-19 15:37:13,483 INFO: errors [in D:\image projec\New folder (2)\app.py:77]
2021-06-19 15:37:15,699 ERROR: Exception on / [GET] [in d:\image projec\new folder (2)\env\lib\site-packages\flask\app.py:1455]
Traceback (most recent call last):
  File "d:\image projec\new folder (2)\env\lib\site-packages\flask\app.py", line 2070, in wsgi_app
    response = self.full_dispatch_request()
  File "d:\image projec\new folder (2)\env\lib\site-packages\flask\app.py", line 1515, in full_dispatch_request
    rv = self.handle_user_exception(e)
  File "d:\image projec\new folder (2)\env\lib\site-packages\flask\app.py", line 1513, in full_dispatch_request
    rv = self.dispatch_request()
  File "d:\image projec\new folder (2)\env\lib\site-packages\flask\app.py", line 1499, in dispatch_request
    return self.ensure_sync(self.view_functions[rule.endpoint])(**req.view_args)
  File "D:\image projec\New folder (2)\app.py", line 25, in index
    return render_template('forms/search_image.html')
  File "d:\image projec\new folder (2)\env\lib\site-packages\flask\templating.py", line 150, in render_template
    ctx.app,
  File "d:\image projec\new folder (2)\env\lib\site-packages\flask\templating.py", line 128, in _render
    rv = template.render(context)
  File "d:\image projec\new folder (2)\env\lib\site-packages\jinja2\environment.py", line 1304, in render
    self.environment.handle_exception()
  File "d:\image projec\new folder (2)\env\lib\site-packages\jinja2\environment.py", line 925, in handle_exception
    raise rewrite_traceback_stack(source=source)
  File "D:\image projec\New folder (2)\templates\forms\search_image.html", line 1, in top-level template code
    {% extends 'layouts/main.html' %}
  File "D:\image projec\New folder (2)\templates\layouts\main.html", line 56, in top-level template code
    <li {% if request.endpoint == 'images' %} class="active" {% endif %}><a href="{{ url_for('images') }}">Images</a></li>
  File "d:\image projec\new folder (2)\env\lib\site-packages\flask\helpers.py", line 338, in url_for
    return appctx.app.handle_url_build_error(error, endpoint, values)
  File "d:\image projec\new folder (2)\env\lib\site-packages\flask\helpers.py", line 326, in url_for
    endpoint, values, method=method, force_external=external
  File "d:\image projec\new folder (2)\env\lib\site-packages\werkzeug\routing.py", line 2305, in build
    raise BuildError(endpoint, values, method, self)
werkzeug.routing.BuildError: Could not build url for endpoint 'images'. Did you mean 'search_image_post' instead?
2021-06-19 15:37:15,865 ERROR: Exception on /favicon.ico [GET] [in d:\image projec\new folder (2)\env\lib\site-packages\flask\app.py:1455]
Traceback (most recent call last):
  File "d:\image projec\new folder (2)\env\lib\site-packages\flask\app.py", line 1513, in full_dispatch_request
    rv = self.dispatch_request()
  File "d:\image projec\new folder (2)\env\lib\site-packages\flask\app.py", line 1489, in dispatch_request
    self.raise_routing_exception(req)
  File "d:\image projec\new folder (2)\env\lib\site-packages\flask\app.py", line 1471, in raise_routing_exception
    raise request.routing_exception  # type: ignore
  File "d:\image projec\new folder (2)\env\lib\site-packages\flask\ctx.py", line 367, in match_request
    result = self.url_adapter.match(return_rule=True)  # type: ignore
  File "d:\image projec\new folder (2)\env\lib\site-packages\werkzeug\routing.py", line 2032, in match
    raise NotFound()
werkzeug.exceptions.NotFound: 404 Not Found: The requested URL was not found on the server. If you entered the URL manually please check your spelling and try again.

During handling of the above exception, another exception occurred:

Traceback (most recent call last):
  File "d:\image projec\new folder (2)\env\lib\site-packages\flask\app.py", line 2070, in wsgi_app
    response = self.full_dispatch_request()
  File "d:\image projec\new folder (2)\env\lib\site-packages\flask\app.py", line 1515, in full_dispatch_request
    rv = self.handle_user_exception(e)
  File "d:\image projec\new folder (2)\env\lib\site-packages\flask\app.py", line 1383, in handle_user_exception
    return self.handle_http_exception(e)
  File "d:\image projec\new folder (2)\env\lib\site-packages\flask\app.py", line 1323, in handle_http_exception
    return self.ensure_sync(handler)(e)
  File "D:\image projec\New folder (2)\app.py", line 53, in not_found_error
    return render_template('errors/404.html'), 404
  File "d:\image projec\new folder (2)\env\lib\site-packages\flask\templating.py", line 150, in render_template
    ctx.app,
  File "d:\image projec\new folder (2)\env\lib\site-packages\flask\templating.py", line 128, in _render
    rv = template.render(context)
  File "d:\image projec\new folder (2)\env\lib\site-packages\jinja2\environment.py", line 1304, in render
    self.environment.handle_exception()
  File "d:\image projec\new folder (2)\env\lib\site-packages\jinja2\environment.py", line 925, in handle_exception
    raise rewrite_traceback_stack(source=source)
  File "D:\image projec\New folder (2)\templates\errors\404.html", line 1, in top-level template code
    {% extends 'layouts/main.html' %}
  File "D:\image projec\New folder (2)\templates\layouts\main.html", line 56, in top-level template code
    <li {% if request.endpoint == 'images' %} class="active" {% endif %}><a href="{{ url_for('images') }}">Images</a></li>
  File "d:\image projec\new folder (2)\env\lib\site-packages\flask\helpers.py", line 338, in url_for
    return appctx.app.handle_url_build_error(error, endpoint, values)
  File "d:\image projec\new folder (2)\env\lib\site-packages\flask\helpers.py", line 326, in url_for
    endpoint, values, method=method, force_external=external
  File "d:\image projec\new folder (2)\env\lib\site-packages\werkzeug\routing.py", line 2305, in build
    raise BuildError(endpoint, values, method, self)
werkzeug.routing.BuildError: Could not build url for endpoint 'images'. Did you mean 'search_image_post' instead?
